Workbook

Sheet Inputs
A1: Plan Finansowy Fjord Anglers — Inputs (wpisuj tutaj)
A2: Żółte pola = edytujesz. Wszystko inne liczone automatycznie w zakładce P&L.
A4: 1. Unit economics (na podstawie Notion)
A5: Średnia wartość transakcji | B5: 2125 | C5: Notion: ~€500 × 4.25 zł
A6: Prowizja na trip (nasz take rate) | B6: 425 | C6: Notion: ~€100
A7: Docelowy CPA (koszt akwizycji) | B7: 105 | C7: Notion: ~€25
A8: Wskaźnik konwersji zapytanie → rezerwacja | B8: 0.3 | C8: 30% standard branżowy
A10: 2. ZUS — stawki miesięczne (zł)
A11: Ulga na start (mies. 1–6) | B11: 432 | C11: Tylko zdrowotna
A12: Mały ZUS (mies. 7–30) | B12: 888 | C12: Społeczne + zdrowotne
A13: Pełny ZUS (mies. 31+) | B13: 2206 | C13: Stawki 2026
A15: 3. Stałe koszty miesięczne (zł)
A16: Narzędzia — faza startu (mies. 1–3) | B16: 65 | C16: Hosting, DB, maile — free tiers
A17: Narzędzia — faza rozpędu (mies. 4–6) | B17: 130
A18: Narzędzia — faza skali (mies. 7–12) | B18: 340
A19: Księgowość | B19: 425 | C19: Biuro rachunkowe
A20: Opłaty bankowe | B20: 45 | C20: Alior firmowe
A21: Bufor / różne | B21: 210
A23: 4. Budżet marketingowy (zł/mies.)
A24: Start (mies. 1–3) | B24: 3190 | C24: Notion: €750
A25: Rozpęd (mies. 4–6) | B25: 6375 | C25: Notion: €1500
A26: Skala (mies. 7–12) | B26: 10625 | C26: Notion: €2500
A28: 5. Udziały założycieli (%)
A29: Tymon (CEO) | B29: 0.7
A30: Krzychu (Head of Fishing) | B30: 0.2
A31: Lukas | B31: 0.1
A33: 6. Prognozowane zapytania/mies. (scenariusz realistyczny)
A34: Miesiąc 1 | B34: 4
A35: Miesiąc 2 | B35: 7
A36: Miesiąc 3 | B36: 10
A37: Miesiąc 4 | B37: 17
A38: Miesiąc 5 | B38: 23
A39: Miesiąc 6 | B39: 30
A40: Miesiąc 7 | B40: 43
A41: Miesiąc 8 | B41: 53
A42: Miesiąc 9 | B42: 63
A43: Miesiąc 10 | B43: 70
A44: Miesiąc 11 | B44: 77
A45: Miesiąc 12 | B45: 80
A47: 7. Gotówka na start (opcjonalnie)
...

Sheet P&L
A1: P&L miesięczny — liczony z zakładki Inputs
A2: Wszystko czarne = formuły. Zmień liczbę w Inputs → cały P&L się przeliczy.
A4: Pozycja | B4: M1 | C4: M2 | D4: M3 | E4: M4 | F4: M5 | G4: M6 | H4: M7 | I4: M8 | J4: M9 | K4: M10 | L4: M11 | M4: M12 | N4: Rok 1
A5: PRZYCHÓD
A6: Zapytania / mies. | B6: =Inputs!B34 -> 4 | C6: =Inputs!B35 -> 7 | D6: =Inputs!B36 -> 10 | E6: =Inputs!B37 -> 17 | F6: =Inputs!B38 -> 23 | G6: =Inputs!B39 -> 30 | H6: =Inputs!B40 -> 43 | I6: =Inputs!B41 -> 53 | J6: =Inputs!B42 -> 63 | K6: =Inputs!B43 -> 70 | L6: =Inputs!B44 -> 77 | M6: =Inputs!B45 -> 80 | N6: =SUM(B6:M6) -> 477
A7: Rezerwacje (zapytania × konwersja) | B7: =ROUND(B6*Inputs!$B$8,0) -> 1 | C7: =ROUND(C6*Inputs!$B$8,0) -> 2 | D7: =ROUND(D6*Inputs!$B$8,0) -> 3 | E7: =ROUND(E6*Inputs!$B$8,0) -> 5 | F7: =ROUND(F6*Inputs!$B$8,0) -> 7 | G7: =ROUND(G6*Inputs!$B$8,0) -> 9 | H7: =ROUND(H6*Inputs!$B$8,0) -> 13 | I7: =ROUND(I6*Inputs!$B$8,0) -> 16 | ... M7: =ROUND(M6*Inputs!$B$8,0) -> 24 | N7: =SUM(B7:M7) -> 143
A8: Przychód (rezerwacje × prowizja) | B8: =B7*Inputs!$B$6 -> 425 | C8: =C7*Inputs!$B$6 -> 850 | D8: =D7*Inputs!$B$6 -> 1275 | E8: =E7*Inputs!$B$6 -> 2125 | F8: =F7*Inputs!$B$6 -> 2975 | G8: =G7*Inputs!$B$6 -> 3825 | H8: =H7*Inputs!$B$6 -> 5525 | I8: =I7*Inputs!$B$6 -> 6800 | ... M8: =M7*Inputs!$B$6 -> 10200 | N8: =SUM(B8:M8) -> 60775
A10: KOSZTY
A11: Narzędzia (hosting, DB, maile) | B11: =Inputs!$B$16 -> 65 | C11: =Inputs!$B$16 -> 65 | D11: =Inputs!$B$16 -> 65 | E11: =Inputs!$B$17 -> 130 | F11: =Inputs!$B$17 -> 130 | G11: =Inputs!$B$17 -> 130 | H11: =Inputs!$B$18 -> 340 | I11: =Inputs!$B$18 -> 340 | J11: =Inputs!$B$18 -> 340 | K11: =Inputs!$B$18 -> 340 | L11: =Inputs!$B$18 -> 340 | M11: =Inputs!$B$18 -> 340 | N11: =SUM(B11:M11) -> 2625
A12: Księgowość | B12: =Inputs!$B$19 -> 425 | C12: =Inputs!$B$19 -> 425 | D12: =Inputs!$B$19 -> 425 | E12: =Inputs!$B$19 -> 425 | F12: =Inputs!$B$19 -> 425 | G12: =Inputs!$B$19 -> 425 | H12: =Inputs!$B$19 -> 425 | I12: =Inputs!$B$19 -> 425 | ... M12: =Inputs!$B$19 -> 425 | N12: =SUM(B12:M12) -> 5100
A13: Opłaty bankowe | B13: =Inputs!$B$20 -> 45 | C13: =Inputs!$B$20 -> 45 | D13: =Inputs!$B$20 -> 45 | E13: =Inputs!$B$20 -> 45 | F13: =Inputs!$B$20 -> 45 | G13: =Inputs!$B$20 -> 45 | H13: =Inputs!$B$20 -> 45 | I13: =Inputs!$B$20 -> 45 | ... M13: =Inputs!$B$20 -> 45 | N13: =SUM(B13:M13) -> 540
A14: Bufor / różne | B14: =Inputs!$B$21 -> 210 | C14: =Inputs!$B$21 -> 210 | D14: =Inputs!$B$21 -> 210 | E14: =Inputs!$B$21 -> 210 | F14: =Inputs!$B$21 -> 210 | G14: =Inputs!$B$21 -> 210 | H14: =Inputs!$B$21 -> 210 | I14: =Inputs!$B$21 -> 210 | ... M14: =Inputs!$B$21 -> 210 | N14: =SUM(B14:M14) -> 2520
A15: Marketing | B15: =Inputs!$B$24 -> 3190 | C15: =Inputs!$B$24 -> 3190 | D15: =Inputs!$B$24 -> 3190 | E15: =Inputs!$B$25 -> 6375 | F15: =Inputs!$B$25 -> 6375 | G15: =Inputs!$B$25 -> 6375 | H15: =Inputs!$B$26 -> 10625 | I15: =Inputs!$B$26 -> 10625 | J15: =Inputs!$B$26 -> 10625 | K15: =Inputs!$B$26 -> 10625 | L15: =Inputs!$B$26 -> 10625 | M15: =Inputs!$B$26 -> 10625 | N15: =SUM(B15:M15) -> 92445
A16: ZUS | B16: =Inputs!$B$11 -> 432 | C16: =Inputs!$B$11 -> 432 | D16: =Inputs!$B$11 -> 432 | E16: =Inputs!$B$11 -> 432 | F16: =Inputs!$B$11 -> 432 | G16: =Inputs!$B$11 -> 432 | H16: =Inputs!$B$12 -> 888 | I16: =Inputs!$B$12 -> 888 | J16: =Inputs!$B$12 -> 888 | K16: =Inputs!$B$12 -> 888 | L16: =Inputs!$B$12 -> 888 | M16: =Inputs!$B$12 -> 888 | N16: =SUM(B16:M16) -> 7920
A17: KOSZTY RAZEM | B17: =SUM(B11:B16) -> 4367 | C17: =SUM(C11:C16) -> 4367 | D17: =SUM(D11:D16) -> 4367 | E17: =SUM(E11:E16) -> 7617 | F17: =SUM(F11:F16) -> 7617 | G17: =SUM(G11:G16) -> 7617 | H17: =SUM(H11:H16) -> 12533 | I17: =SUM(I11:I16) -> 12533 | ... M17: =SUM(M11:M16) -> 12533 | N17: =SUM(B17:M17) -> 111150
A19: WYNIK
A20: Wynik netto (przychód − koszty) | B20: =B8-B17 -> -3942 | C20: =C8-C17 -> -3517 | D20: =D8-D17 -> -3092 | E20: =E8-E17 -> -5492 | F20: =F8-F17 -> -4642 | G20: =G8-G17 -> -3792 | H20: =H8-H17 -> -7008 | I20: =I8-I17 -> -5733 | ... M20: =M8-M17 -> -2333 | N20: =SUM(B20:M20) -> -50375
A21: Skumulowany netto | B21: =B20 -> -3942 | C21: =B21+C20 -> -7459 | D21: =C21+D20 -> -10551 | E21: =D21+E20 -> -16043 | F21: =E21+F20 -> -20685 | G21: =F21+G20 -> -24477 | H21: =G21+H20 -> -31485 | I21: =H21+I20 -> -37218 | J21: =I21+J20 -> -41676 | ... M21: =L21+M20 -> -50375 | N21: =M21 -> -50375
A23: PRÓG RENTOWNOŚCI / MIES.
A24: Rezerwacje potrzebne do BE | B24: =ROUNDUP(B17/Inputs!$B$6,0) -> 11 | C24: =ROUNDUP(C17/Inputs!$B$6,0) -> 11 | D24: =ROUNDUP(D17/Inputs!$B$6,0) -> 11 | E24: =ROUNDUP(E17/Inputs!$B$6,0) -> 18 | F24: =ROUNDUP(F17/Inputs!$B$6,0) -> 18 | G24: =ROUNDUP(G17/Inputs!$B$6,0) -> 18 | H24: =ROUNDUP(H17/Inputs!$B$6,0) -> 30 | I24: =ROUNDUP(I17/Inputs!$B$6,0) -> 30 | ... M24: =ROUNDUP(M17/Inputs!$B$6,0) -> 30 | N24: =SUM(B24:M24) -> 267
A25: Zapytania potrzebne do BE (przy konwersji) | B25: =ROUNDUP(B24/Inputs!$B$8,0) -> 37 | C25: =ROUNDUP(C24/Inputs!$B$8,0) -> 37 | D25: =ROUNDUP(D24/Inputs!$B$8,0) -> 37 | E25: =ROUNDUP(E24/Inputs!$B$8,0) -> 60 | F25: =ROUNDUP(F24/Inputs!$B$8,0) -> 60 | G25: =ROUNDUP(G24/Inputs!$B$8,0) -> 60 | H25: =ROUNDUP(H24/Inputs!$B$8,0) -> 100 | I25: =ROUNDUP(I24/Inputs!$B$8,0) -> 100 | ... M25: =ROUNDUP(M24/Inputs!$B$8,0) -> 100 | N25: =SUM(B25:M25) -> 891

Sheet Wpłaty założycieli
A1: Wpłaty założycieli — wyrównanie do udziałów
A2: Oblicza ile każdy założyciel powinien wpłacić do kasy firmy proporcjonalnie do udziałów, żeby pokryć burn z P&L.
A4: Kwota do pokrycia (zł): | B4: ='P&L'!N21*-1 -> 50375
A5: (domyślnie: skumulowany burn Roku 1 z P&L — możesz wpisać własną kwotę ręcznie w B4)
A7: Założyciel | B7: Udział % | C7: Wpłata do równych udziałów (zł) | D7: Już wpłacone (zł) | E7: Do wpłaty jeszcze (zł)
A8: Tymon (CEO) | B8: =Inputs!B29 -> 0.7 | C8: =$B$4*B8 -> 35262.5 | D8: 0 | E8: =C8-D8 -> 35262.5
A9: Krzychu (Head of Fishing) | B9: =Inputs!B30 -> 0.2 | C9: =$B$4*B9 -> 10075 | D9: 0 | E9: =C9-D9 -> 10075
A10: Lukas | B10: =Inputs!B31 -> 0.1 | C10: =$B$4*B10 -> 5037.5 | D10: 0 | E10: =C10-D10 -> 5037.5
A11: RAZEM | B11: =SUM(B8:B10) -> 1 | C11: =SUM(C8:C10) -> 50375 | D11: =SUM(D8:D10) -> 0 | E11: =SUM(E8:E10) -> 50375
A14: Historia wpłat (dodawaj ręcznie)
A15: Data | B15: Założyciel | C15: Kwota (zł) | D15: Cel / opis
